<sdf version='1.7'>
  <model name='gibbon'>
    <link name='link_1_tip'>
      <inertial>
        <pose>0 0 0 0 -0 0</pose>
        <mass>1e-05</mass>
        <inertia>
          <ixx>1</ixx>
          <ixy>0</ixy>
          <ixz>0</ixz>
          <iyy>1</iyy>
          <iyz>0</iyz>
          <izz>1</izz>
        </inertia>
      </inertial>
    </link>
    <joint name='link_1__link_1_tip' type='revolute'>
      <pose relative_to='link_1_tip'>0 0 -0.1 0 -0 0</pose>
      <parent>link_1_tip</parent>
      <child>link_1</child>
      <axis>
        <xyz>1 0 0</xyz>
        <limit>
          <lower>0</lower>
          <upper>0</upper>
          <effort>0</effort>
          <velocity>0</velocity>
        </limit>
        <dynamics>
          <spring_reference>0</spring_reference>
          <spring_stiffness>0</spring_stiffness>
        </dynamics>
      </axis>
    </joint>
    <link name='link_1'>
      <pose relative_to='link_1__link_1_tip'>0 0 0 0 -0 0</pose>
      <inertial>
        <pose>0 0 -0.399996 0 -0 0</pose>
        <mass>1.00001</mass>
        <inertia>
          <ixx>0.05</ixx>
          <ixy>0</ixy>
          <ixz>0</ixz>
          <iyy>0.05</iyy>
          <iyz>0</iyz>
          <izz>0.01</izz>
        </inertia>
      </inertial>
      <collision name='link_1_collision'>
        <pose>0 0 -0.4 0 -0 0</pose>
        <geometry>
          <cylinder>
            <length>0.8</length>
            <radius>0.01</radius>
          </cylinder>
        </geometry>
        <surface>
          <contact>
            <ode/>
          </contact>
          <friction>
            <ode/>
          </friction>
        </surface>
      </collision>
      <collision name='link_1_gripper_pole_collision_1'>
        <pose>0 0 0 0 -1.5708 0</pose>
        <geometry>
          <cylinder>
            <length>0</length>
            <radius>0.01</radius>
          </cylinder>
        </geometry>
        <surface>
          <contact>
            <ode/>
          </contact>
          <friction>
            <ode/>
          </friction>
        </surface>
      </collision>
      <visual name='link_1_visual'>
        <pose>0 0 -0.4 0 -0 0</pose>
        <geometry>
          <cylinder>
            <length>0.8</length>
            <radius>0.01</radius>
          </cylinder>
        </geometry>
        <material>
          <script>
            <name>Gazebo/Red</name>
            <uri>file://media/materials/scripts/gazebo.material</uri>
          </script>
        </material>
      </visual>
      <visual name='link_1_gripper_pole_visual_1'>
        <pose>0 0 0 0 -1.5708 0</pose>
        <geometry>
          <cylinder>
            <length>0</length>
            <radius>0.01</radius>
          </cylinder>
        </geometry>
        <material>
          <script>
            <name>Gazebo/Red</name>
            <uri>file://media/materials/scripts/gazebo.material</uri>
          </script>
        </material>
      </visual>
    </link>
    <joint name='link_1_left_gripper_joint' type='revolute'>
      <pose relative_to='link_1'>0 0.01 0 0 -1.5708 0</pose>
      <parent>link_1</parent>
      <child>link_1_left_gripper</child>
      <axis>
        <xyz>0 0 1</xyz>
        <limit>
          <lower>0</lower>
          <upper>3</upper>
          <effort>100</effort>
          <velocity>30</velocity>
        </limit>
        <dynamics>
          <spring_reference>0</spring_reference>
          <spring_stiffness>0</spring_stiffness>
        </dynamics>
      </axis>
    </joint>
    <link name='link_1_left_gripper'>
      <pose relative_to='link_1_left_gripper_joint'>0 0 0 0 -0 0</pose>
      <inertial>
        <pose>0 0 0 0 -0 0</pose>
        <mass>0.05</mass>
        <inertia>
          <ixx>1</ixx>
          <ixy>0</ixy>
          <ixz>0</ixz>
          <iyy>1</iyy>
          <iyz>0</iyz>
          <izz>1</izz>
        </inertia>
      </inertial>
      <collision name='link_1_left_gripper_collision'>
        <pose>0.05 0 0 1.5708 -0 1.5708</pose>
        <geometry>
          <box>
            <size>0.001 0.02 0.1</size>
          </box>
        </geometry>
        <surface>
          <contact>
            <ode/>
          </contact>
          <friction>
            <ode>
              <mu>0.001</mu>
              <mu2>0.001</mu2>
            </ode>
          </friction>
        </surface>
      </collision>
      <collision name='link_1_left_gripper_collision_1'>
        <pose>0.104 -0.005 0 0 -0 0.7</pose>
        <geometry>
          <box>
            <size>0.001 0.01 0.02</size>
          </box>
        </geometry>
        <surface>
          <contact>
            <ode/>
          </contact>
          <friction>
            <ode>
              <mu>0.001</mu>
              <mu2>0.001</mu2>
            </ode>
          </friction>
        </surface>
      </collision>
      <visual name='link_1_left_gripper_visual'>
        <pose>0.05 0 0 1.5708 -0 1.5708</pose>
        <geometry>
          <box>
            <size>0.001 0.02 0.1</size>
          </box>
        </geometry>
      </visual>
      <visual name='link_1_left_gripper_visual_1'>
        <pose>0.104 -0.005 0 0 -0 0.7</pose>
        <geometry>
          <box>
            <size>0.001 0.01 0.02</size>
          </box>
        </geometry>
      </visual>
    </link>
    <joint name='link_1_right_gripper_joint' type='revolute'>
      <pose relative_to='link_1'>0 -0.01 0 0 -1.5708 0</pose>
      <parent>link_1</parent>
      <child>link_1_right_gripper</child>
      <axis>
        <xyz>0 0 -1</xyz>
        <limit>
          <lower>0</lower>
          <upper>3</upper>
          <effort>100</effort>
          <velocity>30</velocity>
        </limit>
        <dynamics>
          <spring_reference>0</spring_reference>
          <spring_stiffness>0</spring_stiffness>
        </dynamics>
      </axis>
    </joint>
    <link name='link_1_right_gripper'>
      <pose relative_to='link_1_right_gripper_joint'>0 0 0 0 -0 0</pose>
      <inertial>
        <pose>0 0 0 0 -0 0</pose>
        <mass>0.05</mass>
        <inertia>
          <ixx>1</ixx>
          <ixy>0</ixy>
          <ixz>0</ixz>
          <iyy>1</iyy>
          <iyz>0</iyz>
          <izz>1</izz>
        </inertia>
      </inertial>
      <collision name='link_1_right_gripper_collision'>
        <pose>0.05 0 0 -1.5708 -0 -1.5708</pose>
        <geometry>
          <box>
            <size>0.001 0.02 0.1</size>
          </box>
        </geometry>
        <surface>
          <contact>
            <ode/>
          </contact>
          <friction>
            <ode>
              <mu>0.001</mu>
              <mu2>0.001</mu2>
            </ode>
          </friction>
        </surface>
      </collision>
      <collision name='link_1_right_gripper_collision_1'>
        <pose>0.104 0.005 0 0 0 -0.7</pose>
        <geometry>
          <box>
            <size>0.001 0.01 0.02</size>
          </box>
        </geometry>
        <surface>
          <contact>
            <ode/>
          </contact>
          <friction>
            <ode>
              <mu>0.001</mu>
              <mu2>0.001</mu2>
            </ode>
          </friction>
        </surface>
      </collision>
      <visual name='link_1_right_gripper_visual'>
        <pose>0.05 0 0 -1.5708 -0 -1.5708</pose>
        <geometry>
          <box>
            <size>0.001 0.02 0.1</size>
          </box>
        </geometry>
      </visual>
      <visual name='link_1_right_gripper_visual_1'>
        <pose>0.104 0.005 0 0 0 -0.7</pose>
        <geometry>
          <box>
            <size>0.001 0.01 0.02</size>
          </box>
        </geometry>
      </visual>
    </link>
    <joint name='link_1__link_2' type='revolute'>
      <pose relative_to='link_1'>0.01 0 -0.8 3.14159 -0 0</pose>
      <parent>link_1</parent>
      <child>link_2</child>
      <axis>
        <xyz>1 0 0</xyz>
        <limit>
          <lower>-6.28319</lower>
          <upper>6.28319</upper>
          <effort>100</effort>
          <velocity>30</velocity>
        </limit>
        <dynamics>
          <damping>0</damping>
          <friction>0</friction>
          <spring_reference>0</spring_reference>
          <spring_stiffness>0</spring_stiffness>
        </dynamics>
      </axis>
    </joint>
    <link name='link_2'>
      <pose relative_to='link_1__link_2'>0 0 0 0 -0 0</pose>
      <inertial>
        <pose>0 0 0.400004 0 -0 0</pose>
        <mass>1.00001</mass>
        <inertia>
          <ixx>0.05</ixx>
          <ixy>0</ixy>
          <ixz>0</ixz>
          <iyy>0.05</iyy>
          <iyz>0</iyz>
          <izz>0.01</izz>
        </inertia>
      </inertial>
      <collision name='link_2_collision'>
        <pose>0 0 0.4 0 -0 0</pose>
        <geometry>
          <cylinder>
            <length>0.8</length>
            <radius>0.01</radius>
          </cylinder>
        </geometry>
      </collision>
      <collision name='link_2_gripper_pole_collision_1'>
        <pose>0 0 0.8 0 -1.5708 0</pose>
        <geometry>
          <cylinder>
            <length>0</length>
            <radius>0.01</radius>
          </cylinder>
        </geometry>
      </collision>
      <visual name='link_2_visual'>
        <pose>0 0 0.4 0 -0 0</pose>
        <geometry>
          <cylinder>
            <length>0.8</length>
            <radius>0.01</radius>
          </cylinder>
        </geometry>
      </visual>
      <visual name='link_2_gripper_pole_visual_1'>
        <pose>0 0 0.8 0 -1.5708 0</pose>
        <geometry>
          <cylinder>
            <length>0</length>
            <radius>0.01</radius>
          </cylinder>
        </geometry>
      </visual>
    </link>
    <joint name='link_2_left_gripper_joint' type='revolute'>
      <pose relative_to='link_2'>0 0.01 0.8 0 -1.5708 0</pose>
      <parent>link_2</parent>
      <child>link_2_left_gripper</child>
      <axis>
        <xyz>0 0 1</xyz>
        <limit>
          <lower>0</lower>
          <upper>3</upper>
          <effort>100</effort>
          <velocity>30</velocity>
        </limit>
        <dynamics>
          <spring_reference>0</spring_reference>
          <spring_stiffness>0</spring_stiffness>
        </dynamics>
      </axis>
    </joint>
    <link name='link_2_left_gripper'>
      <pose relative_to='link_2_left_gripper_joint'>0 0 0 0 -0 0</pose>
      <inertial>
        <pose>0 0 0 0 -0 0</pose>
        <mass>0.05</mass>
        <inertia>
          <ixx>1</ixx>
          <ixy>0</ixy>
          <ixz>0</ixz>
          <iyy>1</iyy>
          <iyz>0</iyz>
          <izz>1</izz>
        </inertia>
      </inertial>
      <collision name='link_2_left_gripper_collision'>
        <pose>0.05 0 0 1.5708 -0 1.5708</pose>
        <geometry>
          <box>
            <size>0.001 0.02 0.1</size>
          </box>
        </geometry>
        <surface>
          <contact>
            <ode/>
          </contact>
          <friction>
            <ode>
              <mu>0.001</mu>
              <mu2>0.001</mu2>
            </ode>
          </friction>
        </surface>
      </collision>
      <collision name='link_2_left_gripper_collision_1'>
        <pose>0.104 -0.005 0 0 -0 0.7</pose>
        <geometry>
          <box>
            <size>0.001 0.01 0.02</size>
          </box>
        </geometry>
        <surface>
          <contact>
            <ode/>
          </contact>
          <friction>
            <ode>
              <mu>0.001</mu>
              <mu2>0.001</mu2>
            </ode>
          </friction>
        </surface>
      </collision>
      <visual name='link_2_left_gripper_visual'>
        <pose>0.05 0 0 1.5708 -0 1.5708</pose>
        <geometry>
          <box>
            <size>0.001 0.02 0.1</size>
          </box>
        </geometry>
      </visual>
      <visual name='link_2_left_gripper_visual_1'>
        <pose>0.104 -0.005 0 0 -0 0.7</pose>
        <geometry>
          <box>
            <size>0.001 0.01 0.02</size>
          </box>
        </geometry>
      </visual>
    </link>
    <joint name='link_2_right_gripper_joint' type='revolute'>
      <pose relative_to='link_2'>0 -0.01 0.8 0 -1.5708 0</pose>
      <parent>link_2</parent>
      <child>link_2_right_gripper</child>
      <axis>
        <xyz>0 0 -1</xyz>
        <limit>
          <lower>0</lower>
          <upper>3</upper>
          <effort>100</effort>
          <velocity>30</velocity>
        </limit>
        <dynamics>
          <spring_reference>0</spring_reference>
          <spring_stiffness>0</spring_stiffness>
        </dynamics>
      </axis>
    </joint>
    <link name='link_2_right_gripper'>
      <pose relative_to='link_2_right_gripper_joint'>0 0 0 0 -0 0</pose>
      <inertial>
        <pose>0 0 0 0 -0 0</pose>
        <mass>0.05</mass>
        <inertia>
          <ixx>1</ixx>
          <ixy>0</ixy>
          <ixz>0</ixz>
          <iyy>1</iyy>
          <iyz>0</iyz>
          <izz>1</izz>
        </inertia>
      </inertial>
      <collision name='link_2_right_gripper_collision'>
        <pose>0.05 0 0 -1.5708 -0 -1.5708</pose>
        <geometry>
          <box>
            <size>0.001 0.02 0.1</size>
          </box>
        </geometry>
        <surface>
          <contact>
            <ode/>
          </contact>
          <friction>
            <ode>
              <mu>0.001</mu>
              <mu2>0.001</mu2>
            </ode>
          </friction>
        </surface>
      </collision>
      <collision name='link_2_right_gripper_collision_1'>
        <pose>0.104 0.005 0 0 0 -0.7</pose>
        <geometry>
          <box>
            <size>0.001 0.01 0.02</size>
          </box>
        </geometry>
        <surface>
          <contact>
            <ode/>
          </contact>
          <friction>
            <ode>
              <mu>0.001</mu>
              <mu2>0.001</mu2>
            </ode>
          </friction>
        </surface>
      </collision>
      <visual name='link_2_right_gripper_visual'>
        <pose>0.05 0 0 -1.5708 -0 -1.5708</pose>
        <geometry>
          <box>
            <size>0.001 0.02 0.1</size>
          </box>
        </geometry>
      </visual>
      <visual name='link_2_right_gripper_visual_1'>
        <pose>0.104 0.005 0 0 0 -0.7</pose>
        <geometry>
          <box>
            <size>0.001 0.01 0.02</size>
          </box>
        </geometry>
      </visual>
    </link>
    <joint name='link_2__link_2_tip' type='revolute'>
      <pose relative_to='link_2'>0.02 0 0.9 0 -0 0</pose>
      <parent>link_2</parent>
      <child>link_2_tip</child>
      <axis>
        <xyz>1 0 0</xyz>
        <limit>
          <lower>0</lower>
          <upper>0</upper>
          <effort>0</effort>
          <velocity>0</velocity>
        </limit>
        <dynamics>
          <spring_reference>0</spring_reference>
          <spring_stiffness>0</spring_stiffness>
        </dynamics>
      </axis>
    </joint>
    <link name='link_2_tip'>
      <pose relative_to='link_2__link_2_tip'>0 0 0 0 -0 0</pose>
      <inertial>
        <pose>0 0 0 0 -0 0</pose>
        <mass>1e-05</mass>
        <inertia>
          <ixx>1</ixx>
          <ixy>0</ixy>
          <ixz>0</ixz>
          <iyy>1</iyy>
          <iyz>0</iyz>
          <izz>1</izz>
        </inertia>
      </inertial>
    </link>
    <static>0</static>
    <plugin name='gazebo_ros_control' filename='libgazebo_ros_control.so'>
      <robotNamespace>/gibbon</robotNamespace>
    </plugin>
  </model>
</sdf>
