<sdf version='1.6'>
  <model name='gibbon'>
    <link name='base_link'>
      <inertial>
        <pose>0 0 0 0 -0 0</pose>
        <mass>1.001</mass>
        <inertia>
          <ixx>1.33333</ixx>
          <ixy>0</ixy>
          <ixz>0</ixz>
          <iyy>1.33333</iyy>
          <iyz>0</iyz>
          <izz>1</izz>
        </inertia>
      </inertial>
      <collision name='base_link_fixed_joint_lump__link_1_collision'>
        <pose>0 0 -0.5 0 -0 0</pose>
        <geometry>
          <cylinder>
            <length>1</length>
            <radius>0.01</radius>
          </cylinder>
        </geometry>
      </collision>
      <collision name='base_link_fixed_joint_lump__link_1_gripper_pole_collision_1'>
        <pose>0 0 0 0 -1.5708 0</pose>
        <geometry>
          <cylinder>
            <length>0</length>
            <radius>0.01</radius>
          </cylinder>
        </geometry>
      </collision>
      <visual name='base_link_fixed_joint_lump__link_1_visual'>
        <pose>0 0 -0.5 0 -0 0</pose>
        <geometry>
          <cylinder>
            <length>1</length>
            <radius>0.01</radius>
          </cylinder>
        </geometry>
      </visual>
      <visual name='base_link_fixed_joint_lump__link_1_gripper_pole_visual_1'>
        <pose>0 0 0 0 -1.5708 0</pose>
        <geometry>
          <cylinder>
            <length>0</length>
            <radius>0.01</radius>
          </cylinder>
        </geometry>
      </visual>
    </link>
    <joint name='link_1_left_gripper_joint' type='revolute'>
      <pose relative_to='base_link'>0 0.01 0 0 -1.5708 0</pose>
      <parent>base_link</parent>
      <child>link_1_left_gripper</child>
      <axis>
        <xyz>0 0 1</xyz>
        <limit>
          <lower>0</lower>
          <upper>0.548</upper>
          <effort>100000</effort>
          <velocity>3.14</velocity>
        </limit>
        <dynamics>
          <spring_reference>0</spring_reference>
          <spring_stiffness>0</spring_stiffness>
        </dynamics>
      </axis>
    </joint>
    <link name='link_1_left_gripper'>
      <pose relative_to='link_1_left_gripper_joint'>0 0 0 0 -0 0</pose>
      <inertial>
        <pose>0 0 0 0 -0 0</pose>
        <mass>0.05</mass>
        <inertia>
          <ixx>1</ixx>
          <ixy>0</ixy>
          <ixz>0</ixz>
          <iyy>1</iyy>
          <iyz>0</iyz>
          <izz>1</izz>
        </inertia>
      </inertial>
      <collision name='link_1_left_gripper_collision'>
        <pose>0.05 0 0 1.5708 -0 1.5708</pose>
        <geometry>
          <box>
            <size>0.001 0.02 0.1</size>
          </box>
        </geometry>
      </collision>
      <collision name='link_1_left_gripper_collision_1'>
        <pose>0.1 -0.005 0 0 -0 0</pose>
        <geometry>
          <box>
            <size>0.001 0.01 0.02</size>
          </box>
        </geometry>
      </collision>
      <visual name='link_1_left_gripper_visual'>
        <pose>0.05 0 0 1.5708 -0 1.5708</pose>
        <geometry>
          <box>
            <size>0.001 0.02 0.1</size>
          </box>
        </geometry>
      </visual>
      <visual name='link_1_left_gripper_visual_1'>
        <pose>0.1 -0.005 0 0 -0 0</pose>
        <geometry>
          <box>
            <size>0.001 0.01 0.02</size>
          </box>
        </geometry>
      </visual>
    </link>
    <joint name='link_1_right_gripper_joint' type='revolute'>
      <pose relative_to='base_link'>0 -0.01 0 0 -1.5708 0</pose>
      <parent>base_link</parent>
      <child>link_1_right_gripper</child>
      <axis>
        <xyz>0 0 -1</xyz>
        <limit>
          <lower>0</lower>
          <upper>0.548</upper>
          <effort>100000</effort>
          <velocity>3.14</velocity>
        </limit>
        <dynamics>
          <spring_reference>0</spring_reference>
          <spring_stiffness>0</spring_stiffness>
        </dynamics>
      </axis>
    </joint>
    <link name='link_1_right_gripper'>
      <pose relative_to='link_1_right_gripper_joint'>0 0 0 0 -0 0</pose>
      <inertial>
        <pose>0 0 0 0 -0 0</pose>
        <mass>0.05</mass>
        <inertia>
          <ixx>1</ixx>
          <ixy>0</ixy>
          <ixz>0</ixz>
          <iyy>1</iyy>
          <iyz>0</iyz>
          <izz>1</izz>
        </inertia>
      </inertial>
      <collision name='link_1_right_gripper_collision'>
        <pose>0.05 0 0 -1.5708 -0 -1.5708</pose>
        <geometry>
          <box>
            <size>0.001 0.02 0.1</size>
          </box>
        </geometry>
      </collision>
      <collision name='link_1_right_gripper_collision_1'>
        <pose>0.1 0.005 0 0 -0 0</pose>
        <geometry>
          <box>
            <size>0.001 0.01 0.02</size>
          </box>
        </geometry>
      </collision>
      <visual name='link_1_right_gripper_visual'>
        <pose>0.05 0 0 -1.5708 -0 -1.5708</pose>
        <geometry>
          <box>
            <size>0.001 0.02 0.1</size>
          </box>
        </geometry>
      </visual>
      <visual name='link_1_right_gripper_visual_1'>
        <pose>0.1 0.005 0 0 -0 0</pose>
        <geometry>
          <box>
            <size>0.001 0.01 0.02</size>
          </box>
        </geometry>
      </visual>
    </link>
    <joint name='link_1__link_2' type='revolute'>
      <pose relative_to='base_link'>0.01 0 -1 0 -0 0</pose>
      <parent>base_link</parent>
      <child>link_2</child>
      <axis>
        <xyz>1 0 0</xyz>
        <limit>
          <lower>-3.14159</lower>
          <upper>3.14159</upper>
          <effort>0</effort>
          <velocity>0</velocity>
        </limit>
        <dynamics>
          <damping>0</damping>
          <friction>0.1</friction>
          <spring_reference>0</spring_reference>
          <spring_stiffness>0</spring_stiffness>
        </dynamics>
      </axis>
    </joint>
    <link name='link_2'>
      <pose relative_to='link_1__link_2'>0 0 0 0 -0 0</pose>
      <inertial>
        <pose>2e-05 0 -0.000999 0 -0 0</pose>
        <mass>1.001</mass>
        <inertia>
          <ixx>1.33433</ixx>
          <ixy>0</ixy>
          <ixz>1.998e-05</ixz>
          <iyy>1.33433</iyy>
          <iyz>0</iyz>
          <izz>1</izz>
        </inertia>
      </inertial>
      <collision name='link_2_collision'>
        <pose>0.02 0 -0.5 0 -0 0</pose>
        <geometry>
          <cylinder>
            <length>1</length>
            <radius>0.01</radius>
          </cylinder>
        </geometry>
      </collision>
      <collision name='link_2_gripper_pole_collision_1'>
        <pose>0.02 0 -1 0 1.5708 0</pose>
        <geometry>
          <cylinder>
            <length>0</length>
            <radius>0.01</radius>
          </cylinder>
        </geometry>
      </collision>
      <visual name='link_2_visual'>
        <pose>0.02 0 -0.5 0 -0 0</pose>
        <geometry>
          <cylinder>
            <length>1</length>
            <radius>0.01</radius>
          </cylinder>
        </geometry>
      </visual>
      <visual name='link_2_gripper_pole_visual_1'>
        <pose>0.02 0 -1 0 1.5708 0</pose>
        <geometry>
          <cylinder>
            <length>0</length>
            <radius>0.01</radius>
          </cylinder>
        </geometry>
      </visual>
    </link>
    <joint name='link_2_left_gripper_joint' type='revolute'>
      <pose relative_to='link_2'>0.02 0.01 -1 0 1.5708 0</pose>
      <parent>link_2</parent>
      <child>link_2_left_gripper</child>
      <axis>
        <xyz>0 0 1</xyz>
        <limit>
          <lower>0</lower>
          <upper>0.548</upper>
          <effort>100000</effort>
          <velocity>3.14</velocity>
        </limit>
        <dynamics>
          <spring_reference>0</spring_reference>
          <spring_stiffness>0</spring_stiffness>
        </dynamics>
      </axis>
    </joint>
    <link name='link_2_left_gripper'>
      <pose relative_to='link_2_left_gripper_joint'>0 0 0 0 -0 0</pose>
      <inertial>
        <pose>0 0 0 0 -0 0</pose>
        <mass>0.05</mass>
        <inertia>
          <ixx>1</ixx>
          <ixy>0</ixy>
          <ixz>0</ixz>
          <iyy>1</iyy>
          <iyz>0</iyz>
          <izz>1</izz>
        </inertia>
      </inertial>
      <collision name='link_2_left_gripper_collision'>
        <pose>0.05 0 0 1.5708 -0 1.5708</pose>
        <geometry>
          <box>
            <size>0.001 0.02 0.1</size>
          </box>
        </geometry>
      </collision>
      <collision name='link_2_left_gripper_collision_1'>
        <pose>0.1 -0.005 0 0 -0 0</pose>
        <geometry>
          <box>
            <size>0.001 0.01 0.02</size>
          </box>
        </geometry>
      </collision>
      <visual name='link_2_left_gripper_visual'>
        <pose>0.05 0 0 1.5708 -0 1.5708</pose>
        <geometry>
          <box>
            <size>0.001 0.02 0.1</size>
          </box>
        </geometry>
      </visual>
      <visual name='link_2_left_gripper_visual_1'>
        <pose>0.1 -0.005 0 0 -0 0</pose>
        <geometry>
          <box>
            <size>0.001 0.01 0.02</size>
          </box>
        </geometry>
      </visual>
    </link>
    <joint name='link_2_right_gripper_joint' type='revolute'>
      <pose relative_to='link_2'>0.02 -0.01 -1 0 1.5708 0</pose>
      <parent>link_2</parent>
      <child>link_2_right_gripper</child>
      <axis>
        <xyz>0 0 -1</xyz>
        <limit>
          <lower>0</lower>
          <upper>0.548</upper>
          <effort>100000</effort>
          <velocity>3.14</velocity>
        </limit>
        <dynamics>
          <spring_reference>0</spring_reference>
          <spring_stiffness>0</spring_stiffness>
        </dynamics>
      </axis>
    </joint>
    <link name='link_2_right_gripper'>
      <pose relative_to='link_2_right_gripper_joint'>0 0 0 0 -0 0</pose>
      <inertial>
        <pose>0 0 0 0 -0 0</pose>
        <mass>0.05</mass>
        <inertia>
          <ixx>1</ixx>
          <ixy>0</ixy>
          <ixz>0</ixz>
          <iyy>1</iyy>
          <iyz>0</iyz>
          <izz>1</izz>
        </inertia>
      </inertial>
      <collision name='link_2_right_gripper_collision'>
        <pose>0.05 0 0 -1.5708 -0 -1.5708</pose>
        <geometry>
          <box>
            <size>0.001 0.02 0.1</size>
          </box>
        </geometry>
      </collision>
      <collision name='link_2_right_gripper_collision_1'>
        <pose>0.1 0.005 0 0 -0 0</pose>
        <geometry>
          <box>
            <size>0.001 0.01 0.02</size>
          </box>
        </geometry>
      </collision>
      <visual name='link_2_right_gripper_visual'>
        <pose>0.05 0 0 -1.5708 -0 -1.5708</pose>
        <geometry>
          <box>
            <size>0.001 0.02 0.1</size>
          </box>
        </geometry>
      </visual>
      <visual name='link_2_right_gripper_visual_1'>
        <pose>0.1 0.005 0 0 -0 0</pose>
        <geometry>
          <box>
            <size>0.001 0.01 0.02</size>
          </box>
        </geometry>
      </visual>
    </link>
    <static>0</static>
    <plugin name='gazebo_ros_control' filename='libgazebo_ros_control.so'>
      <robotNamespace>/gibbon</robotNamespace>
    </plugin>
  </model>
</sdf>
