<?xml version="1.0" ?>
<!-- =================================================================================== -->
<!-- |    This document was autogenerated by xacro from gibbon.xacro                   | -->
<!-- |    EDITING THIS FILE BY HAND IS NOT RECOMMENDED                                 | -->
<!-- =================================================================================== -->
<robot name="gibbon">
  <material name="grey1">
    <color rgba="0.7 0.7 0.7 1"/>
  </material>
  <material name="grey2">
    <color rgba="0.9 0.9 0.9 1"/>
  </material>
  <link name="base_link"/>
  <joint name="base_link__link_1" type="fixed">
    <parent link="base_link"/>
    <child link="link_1"/>
    <origin rpy="0 0 0" xyz="0 0 0"/>
  </joint>
  <link name="link_1">
    <visual>
      <origin rpy="0 0 0" xyz="0 0 -0.5"/>
      <material name="grey2"/>
      <geometry>
        <cylinder length="1" radius="0.01"/>
      </geometry>
    </visual>
    <collision>
      <origin rpy="0 0 0" xyz="0 0 -0.5"/>
      <geometry>
        <cylinder length="1" radius="0.01"/>
      </geometry>
    </collision>
    <inertial>
      <mass value="1.0"/>
      <inertia ixx="0.3333333333333333" ixy="0.0" ixz="0.0" iyy="0.3333333333333333" iyz="0.0" izz="0.0"/>
    </inertial>
  </link>
  <link name="link_2">
    <visual>
      <origin rpy="0 0 0" xyz="0.02 0 -0.5"/>
      <material name="grey1"/>
      <geometry>
        <cylinder length="1" radius="0.01"/>
      </geometry>
    </visual>
    <collision>
      <origin rpy="0 0 0" xyz="0.02 0 -0.5"/>
      <geometry>
        <cylinder length="1" radius="0.01"/>
      </geometry>
    </collision>
    <inertial>
      <mass value="1.0"/>
      <inertia ixx="0.3333333333333333" ixy="0.0" ixz="0.0" iyy="0.3333333333333333" iyz="0.0" izz="0.0"/>
    </inertial>
  </link>
  <joint name="link_1__link_2" type="revolute">
    <parent link="link_1"/>
    <child link="link_2"/>
    <limit effort="0" lower="-3.141592653589793" upper="3.141592653589793" velocity="0"/>
    <origin rpy="0 0 0" xyz="0.01 0 -1"/>
    <!-- <dynamics damping="0.001"/> -->
    <dynamics friction="0.1"/>
  </joint>
  <transmission name="link_1__link_2_trans">
    <type>transmission_interface/SimpleTransmission</type>
    <actuator name="$link_1__link_2_motor">
      <hardwareInterface>hardware_interface/PositionJointInterface</hardwareInterface>
      <mechanicalReduction>1</mechanicalReduction>
    </actuator>
    <joint name="link_1__link_2">
      <hardwareInterface>hardware_interface/PositionJointInterface</hardwareInterface>
    </joint>
  </transmission>
  <joint name="link_1__gripper" type="fixed">
    <parent link="link_1"/>
    <child link="link_1_gripper_pole"/>
    <origin rpy="0 -1.5707963267948966 0" xyz="0 0 0"/>
  </joint>
  <joint name="link_2__gripper" type="fixed">
    <parent link="link_2"/>
    <child link="link_2_gripper_pole"/>
    <origin rpy="0 1.5707963267948966 0" xyz="0.02 0 -1"/>
  </joint>
  <link name="link_1_gripper_pole">
    <visual>
      <geometry>
        <cylinder length="0.0" radius="0.01"/>
      </geometry>
      <origin rpy="0 0 0 " xyz="0 0 0"/>
    </visual>
    <collision>
      <geometry>
        <cylinder length="0.0" radius="0.01"/>
      </geometry>
      <origin rpy="0 0 0 " xyz="0 0 0"/>
    </collision>
    <inertial>
      <mass value="0.001"/>
      <inertia ixx="1.0" ixy="0.0" ixz="0.0" iyy="1.0" iyz="0.0" izz="1.0"/>
    </inertial>
  </link>
  <link name="link_2_gripper_pole">
    <visual>
      <geometry>
        <cylinder length="0.0" radius="0.01"/>
      </geometry>
      <origin rpy="0 0 0 " xyz="0 0 0"/>
    </visual>
    <collision>
      <geometry>
        <cylinder length="0.0" radius="0.01"/>
      </geometry>
      <origin rpy="0 0 0 " xyz="0 0 0"/>
    </collision>
    <inertial>
      <mass value="0.001"/>
      <inertia ixx="1.0" ixy="0.0" ixz="0.0" iyy="1.0" iyz="0.0" izz="1.0"/>
    </inertial>
  </link>
  <joint name="link_1_left_gripper_joint" type="revolute">
    <axis xyz="0 0 1"/>
    <limit effort="100000.0" lower="0.0" upper="0.548" velocity="3.14"/>
    <origin rpy="0 0 0" xyz="0.0 0.01 0"/>
    <parent link="link_1_gripper_pole"/>
    <child link="link_1_left_gripper"/>
  </joint>
  <transmission name="link_1_left_gripper_joint_trans">
    <type>transmission_interface/SimpleTransmission</type>
    <actuator name="${link_name}_left_gripper_joint_motor">
      <hardwareInterface>hardware_interface/PositionJointInterface</hardwareInterface>
      <mechanicalReduction>1</mechanicalReduction>
    </actuator>
    <joint name="link_1_left_gripper_joint">
      <hardwareInterface>hardware_interface/PositionJointInterface</hardwareInterface>
    </joint>
  </transmission>
  <link name="link_1_left_gripper">
    <visual>
      <origin rpy="1.5707963267948966 0 1.5707963267948966" xyz="0.05 0 0"/>
      <geometry>
        <box size="0.001 0.02 0.1"/>
      </geometry>
    </visual>
    <collision>
      <geometry>
        <box size="0.001 0.02 0.1"/>
      </geometry>
      <origin rpy="1.5707963267948966 0 1.5707963267948966" xyz="0.05 0 0"/>
    </collision>
    <visual>
      <origin rpy="0 0 0" xyz="0.1 -0.005 0"/>
      <geometry>
        <box size="0.001 0.01 0.02"/>
      </geometry>
    </visual>
    <collision>
      <geometry>
        <box size="0.001 0.01 0.02"/>
      </geometry>
      <origin rpy="0 0 0" xyz="0.1 -0.005 0"/>
    </collision>
    <inertial>
      <mass value="0.05"/>
      <inertia ixx="1.0" ixy="0.0" ixz="0.0" iyy="1.0" iyz="0.0" izz="1.0"/>
    </inertial>
  </link>
  <joint name="link_1_right_gripper_joint" type="revolute">
    <axis xyz="0 0 -1"/>
    <limit effort="100000.0" lower="0.0" upper="0.548" velocity="3.14"/>
    <origin rpy="0 0 0" xyz="0.0 -0.01 0"/>
    <parent link="link_1_gripper_pole"/>
    <child link="link_1_right_gripper"/>
  </joint>
  <transmission name="link_1_right_gripper_joint_trans">
    <type>transmission_interface/SimpleTransmission</type>
    <actuator name="${link_name}_right_gripper_joint_motor">
      <hardwareInterface>hardware_interface/PositionJointInterface</hardwareInterface>
      <mechanicalReduction>1</mechanicalReduction>
    </actuator>
    <joint name="link_1_right_gripper_joint">
      <hardwareInterface>hardware_interface/PositionJointInterface</hardwareInterface>
    </joint>
  </transmission>
  <link name="link_1_right_gripper">
    <visual>
      <origin rpy="-1.5707963267948966 0 -1.5707963267948966" xyz="0.05 0 0"/>
      <geometry>
        <box size="0.001 0.02 0.1"/>
      </geometry>
    </visual>
    <collision>
      <geometry>
        <box size="0.001 0.02 0.1"/>
      </geometry>
      <origin rpy="-1.5707963267948966 0 -1.5707963267948966" xyz="0.05 0 0"/>
    </collision>
    <visual>
      <origin rpy="0 0 0" xyz="0.1 0.005 0"/>
      <geometry>
        <box size="0.001 0.01 0.02"/>
      </geometry>
    </visual>
    <collision>
      <geometry>
        <box size="0.001 0.01 0.02"/>
      </geometry>
      <origin rpy="0 0 0" xyz="0.1 0.005 0"/>
    </collision>
    <inertial>
      <mass value="0.05"/>
      <inertia ixx="1.0" ixy="0.0" ixz="0.0" iyy="1.0" iyz="0.0" izz="1.0"/>
    </inertial>
  </link>
  <joint name="link_2_left_gripper_joint" type="revolute">
    <axis xyz="0 0 1"/>
    <limit effort="100000.0" lower="0.0" upper="0.548" velocity="3.14"/>
    <origin rpy="0 0 0" xyz="0.0 0.01 0"/>
    <parent link="link_2_gripper_pole"/>
    <child link="link_2_left_gripper"/>
  </joint>
  <transmission name="link_2_left_gripper_joint_trans">
    <type>transmission_interface/SimpleTransmission</type>
    <actuator name="${link_name}_left_gripper_joint_motor">
      <hardwareInterface>hardware_interface/PositionJointInterface</hardwareInterface>
      <mechanicalReduction>1</mechanicalReduction>
    </actuator>
    <joint name="link_2_left_gripper_joint">
      <hardwareInterface>hardware_interface/PositionJointInterface</hardwareInterface>
    </joint>
  </transmission>
  <link name="link_2_left_gripper">
    <visual>
      <origin rpy="1.5707963267948966 0 1.5707963267948966" xyz="0.05 0 0"/>
      <geometry>
        <box size="0.001 0.02 0.1"/>
      </geometry>
    </visual>
    <collision>
      <geometry>
        <box size="0.001 0.02 0.1"/>
      </geometry>
      <origin rpy="1.5707963267948966 0 1.5707963267948966" xyz="0.05 0 0"/>
    </collision>
    <visual>
      <origin rpy="0 0 0" xyz="0.1 -0.005 0"/>
      <geometry>
        <box size="0.001 0.01 0.02"/>
      </geometry>
    </visual>
    <collision>
      <geometry>
        <box size="0.001 0.01 0.02"/>
      </geometry>
      <origin rpy="0 0 0" xyz="0.1 -0.005 0"/>
    </collision>
    <inertial>
      <mass value="0.05"/>
      <inertia ixx="1.0" ixy="0.0" ixz="0.0" iyy="1.0" iyz="0.0" izz="1.0"/>
    </inertial>
  </link>
  <joint name="link_2_right_gripper_joint" type="revolute">
    <axis xyz="0 0 -1"/>
    <limit effort="100000.0" lower="0.0" upper="0.548" velocity="3.14"/>
    <origin rpy="0 0 0" xyz="0.0 -0.01 0"/>
    <parent link="link_2_gripper_pole"/>
    <child link="link_2_right_gripper"/>
  </joint>
  <transmission name="link_2_right_gripper_joint_trans">
    <type>transmission_interface/SimpleTransmission</type>
    <actuator name="${link_name}_right_gripper_joint_motor">
      <hardwareInterface>hardware_interface/PositionJointInterface</hardwareInterface>
      <mechanicalReduction>1</mechanicalReduction>
    </actuator>
    <joint name="link_2_right_gripper_joint">
      <hardwareInterface>hardware_interface/PositionJointInterface</hardwareInterface>
    </joint>
  </transmission>
  <link name="link_2_right_gripper">
    <visual>
      <origin rpy="-1.5707963267948966 0 -1.5707963267948966" xyz="0.05 0 0"/>
      <geometry>
        <box size="0.001 0.02 0.1"/>
      </geometry>
    </visual>
    <collision>
      <geometry>
        <box size="0.001 0.02 0.1"/>
      </geometry>
      <origin rpy="-1.5707963267948966 0 -1.5707963267948966" xyz="0.05 0 0"/>
    </collision>
    <visual>
      <origin rpy="0 0 0" xyz="0.1 0.005 0"/>
      <geometry>
        <box size="0.001 0.01 0.02"/>
      </geometry>
    </visual>
    <collision>
      <geometry>
        <box size="0.001 0.01 0.02"/>
      </geometry>
      <origin rpy="0 0 0" xyz="0.1 0.005 0"/>
    </collision>
    <inertial>
      <mass value="0.05"/>
      <inertia ixx="1.0" ixy="0.0" ixz="0.0" iyy="1.0" iyz="0.0" izz="1.0"/>
    </inertial>
  </link>
  <gazebo>
    <plugin filename="libgazebo_ros_control.so" name="gazebo_ros_control">
      <robotNamespace>/gibbon</robotNamespace>
    </plugin>
  </gazebo>
</robot>

